Workbook

Sheet Config
A1: Key | B1: Value
A2: RegistrationCode | B2: RRDIGITAL
A3: RegistrationClose | B3: 2026-06-08T10:00:00Z
A4: GroupDrawDate | B4: 2026-06-08T11:00:00Z
A5: GroupPrefsOpen | B5: 2026-06-09T08:00:00Z
A6: GroupPrefsClose | B6: 2026-06-11T18:00:00Z
A7: GroupScoringOpen | B7: 2026-06-11T19:00:00Z
A8: GroupScoringClose | B8: 2026-06-28T06:00:00Z
A9: KnockoutPrefsOpen | B9: 2026-06-28T15:00:00Z
A10: KnockoutPrefsClose | B10: 2026-06-29T19:00:00Z
A11: KnockoutScoringOpen | B11: 2026-06-29T19:00:00Z
A12: KnockoutScoringClose | B12: 2026-07-20T07:00:00Z

Sheet Teams
A1: Team Name | B1: FIFA Ranking | C1: Tier | D1: Flag Emoji | E1: Group
A2: Argentina | B2: 1 | C2: 1 | D2: https://flagcdn.com/w40/ar.png | E2: Group J
A3: Spain | B3: 2 | C3: 1 | D3: https://flagcdn.com/w40/es.png | E3: Group H
A4: France | B4: 3 | C4: 1 | D4: https://flagcdn.com/w40/fr.png | E4: Group I
A5: England | B5: 4 | C5: 1 | D5: https://flagcdn.com/w40/gb-eng.png | E5: Group L
A6: Portugal | B6: 5 | C6: 1 | D6: https://flagcdn.com/w40/pt.png | E6: Group K
A7: Brazil | B7: 6 | C7: 1 | D7: https://flagcdn.com/w40/br.png | E7: Group C
A8: Morocco | B8: 7 | C8: 1 | D8: https://flagcdn.com/w40/ma.png | E8: Group C
A9: Netherlands | B9: 8 | C9: 1 | D9: https://flagcdn.com/w40/nl.png | E9: Group F
A10: Belgium | B10: 9 | C10: 1 | D10: https://flagcdn.com/w40/be.png | E10: Group G
A11: Germany | B11: 10 | C11: 1 | D11: https://flagcdn.com/w40/de.png | E11: Group E
A12: Croatia | B12: 11 | C12: 1 | D12: https://flagcdn.com/w40/hr.png | E12: Group L
A13: Colombia | B13: 13 | C13: 1 | D13: https://flagcdn.com/w40/co.png | E13: Group K
... A49: New Zealand | B49: 85 | C49: 3 | D49: https://flagcdn.com/w40/nz.png | E49: Group G

Sheet Squads
A1: Team Name | B1: Player Name | C1: Position | D1: Shirt Number | E1: PlayerPrice
A2: Mexico | B2: Raul Rangel | C2: GK | D2: 1 | E2: 100
A3: Mexico | B3: Jorge Sanchez | C3: DF | D3: 2 | E3: 100
A4: Mexico | B4: Cesar Montes | C4: DF | D4: 3 | E4: 100
A5: Mexico | B5: Edson Alvarez | C5: DF | D5: 4 | E5: 100
A6: Mexico | B6: Johan Vasquez | C6: DF | D6: 5 | E6: 100
A7: Mexico | B7: Erik Lira | C7: MF | D7: 6 | E7: 100
A8: Mexico | B8: Luis Romo | C8: MF | D8: 7 | E8: 100
A9: Mexico | B9: Alvaro Fidalgo | C9: MF | D9: 8 | E9: 100
A10: Mexico | B10: Raul Jimenez | C10: FW | D10: 9 | E10: 100
A11: Mexico | B11: Alexis Vega | C11: FW | D11: 10 | E11: 100
A12: Mexico | B12: Santiago Gimenez | C12: FW | D12: 11 | E12: 100
A13: Mexico | B13: Carlos Acevedo | C13: GK | D13: 12 | E13: 100
... A27: Mexico | B27: Brian Gutierrez | C27: MF | D27: 26 | E27: 100
A28: South Africa | B28: Ronwen Williams | C28: GK | E28: 100
A29: South Africa | B29: Ricardo Goss | C29: GK | E29: 100
A30: South Africa | B30: Sipho Chaine | C30: GK | E30: 100
A31: South Africa | B31: Aubrey Modiba | C31: DF | E31: 100
A32: South Africa | B32: Khuliso Mudau | C32: DF | E32: 100
A33: South Africa | B33: Nkosinathi Sibisi | C33: DF | E33: 100
A34: South Africa | B34: Mbekezeli Mbokazi | C34: DF | E34: 100
A35: South Africa | B35: Ime Okon | C35: DF | E35: 100
A36: South Africa | B36: Samukele Kabini | C36: DF | E36: 100
A37: South Africa | B37: Khulumani Ndamane | C37: DF | E37: 100
A38: South Africa | B38: Thabang Matuludi | C38: DF | E38: 100
A39: South Africa | B39: Kamogelo Sebelebele | C39: DF | E39: 100
... A79: South Korea | B79: Oh Hyeon-gyu | C79: FW | E79: 100
A80: Czech Republic | B80: Matej Kovar | C80: GK | D80: 1 | E80: 100
A81: Czech Republic | B81: David Zima | C81: DF | D81: 2 | E81: 100
A82: Czech Republic | B82: Tomas Holes | C82: DF | D82: 3 | E82: 100
A83: Czech Republic | B83: Robin Hranac | C83: DF | D83: 4 | E83: 100
A84: Czech Republic | B84: Vladimir Coufal | C84: DF | D84: 5 | E84: 100
A85: Czech Republic | B85: Stepan Chaloupek | C85: DF | D85: 6 | E85: 100
A86: Czech Republic | B86: Ladislav Krejci | C86: DF | D86: 7 | E86: 100
A87: Czech Republic | B87: Vladimir Darida | C87: MF | D87: 8 | E87: 100
A88: Czech Republic | B88: Adam Hlozek | C88: FW | D88: 9 | E88: 100
A89: Czech Republic | B89: Patrik Schick | C89: FW | D89: 10 | E89: 100
A90: Czech Republic | B90: Jan Kuchta | C90: FW | D90: 11 | E90: 100
A91: Czech Republic | B91: Lukas Cerv | C91: MF | D91: 12 | E91: 100
... A105: Czech Republic | B105: Denis Visinsky | C105: FW | D105: 26 | E105: 100
...

Sheet Players
A1: Player ID | B1: Name | C1: PIN | D1: Registered At
A2: P4895871 | B2: Tim Pickup | C2: 9610 | D2: 2026-06-01T12:54:49.587Z
A3: P8241942 | B3: Chris Barrow | C3: 1990 | D3: 2026-06-01T13:00:24.194Z
A4: P8749573 | B4: Drew Whittaker | C4: 1234 | D4: 2026-06-01T13:01:14.957Z
A5: P6355314 | B5: Dan Newton | C5: 538633 | D5: 2026-06-01T13:13:55.531Z
A6: P8907665 | B6: Gregor Fotheringham | C6: 1966 | D6: 2026-06-01T14:41:30.767Z
A7: P2457756 | B7: Jordan | C7: 111343 | D7: 2026-06-02T06:20:45.775Z
A8: P2566247 | B8: Patrick Harrison | C8: 8980 | D8: 2026-06-02T06:54:16.624Z
A9: P2845818 | B9: James Pemberton | C9: 1908 | D9: 2026-06-02T07:11:24.581Z
A10: P5028919 | B10: Chun-Ho | C10: 963852 | D10: 2026-06-02T08:05:02.891Z
A11: P32865210 | B11: Connor Morgan | C11: 9352 | D11: 2026-06-02T08:52:08.652Z
A12: P40339611 | B12: George Payne | C12: 1854 | D12: 2026-06-02T10:16:43.396Z
A13: P79919012 | B13: Ryan Harlow | C13: 81514 | D13: 2026-06-02T10:39:59.190Z
... A21: P76426320 | B21: Kidd | C21: 1985 | D21: 2026-06-05T12:16:04.263Z

Sheet Allocations
A1: Player ID | B1: Player Name | C1: Team Name | D1: Tier
A2: P4895871 | B2: Tim Pickup | C2: Portugal | D2: 1
A3: P4895871 | B3: Tim Pickup | C3: Ecuador | D3: 2
A4: P4895871 | B4: Tim Pickup | C4: Haiti | D4: 3
A5: P8241942 | B5: Chris Barrow | C5: Belgium | D5: 1
A6: P8241942 | B6: Chris Barrow | C6: Panama | D6: 2
A7: P8241942 | B7: Chris Barrow | C7: DR Congo | D7: 3
A8: P8749573 | B8: Drew Whittaker | C8: Croatia | D8: 1
A9: P8749573 | B9: Drew Whittaker | C9: Ivory Coast | D9: 2
A10: P8749573 | B10: Drew Whittaker | C10: Cape Verde | D10: 3
A11: P6355314 | B11: Dan Newton | C11: United States | D11: 1
A12: P6355314 | B12: Dan Newton | C12: Switzerland | D12: 2
A13: P6355314 | B13: Dan Newton | C13: Qatar | D13: 3
... A61: P76426320 | B61: Kidd | C61: Qatar | D61: 3

Sheet GroupPreferences
A1: Player ID | B1: Player Name | C1: Team Name | D1: Tier | E1: Captain Name | F1: 2 Mechanism
A2: P4895871 | B2: Tim Pickup | C2: Portugal | D2: 1 | E2: Bruno Fernandes
A3: P4895871 | B3: Tim Pickup | C3: Ecuador | D3: 2 | E3: Moises Caicedo | F3: conceded
A4: P4895871 | B4: Tim Pickup | C4: Haiti | D4: 3 | E4: Duckens Nazon
A5: P39011219 | B5: Jak Kenworthy | C5: England | D5: 1 | E5: Harry Kane
A6: P39011219 | B6: Jak Kenworthy | C6: Ivory Coast | D6: 2 | E6: Amad Diallo | F6: scored
A7: P39011219 | B7: Jak Kenworthy | C7: Saudi Arabia | D7: 3 | E7: Salem Al-Dawsari
A8: P55168715 | B8: Audrey | C8: Morocco | D8: 1 | E8: Achraf Hakimi
A9: P55168715 | B9: Audrey | C9: Canada | D9: 2 | E9: Alphonso Davies | F9: scored
A10: P55168715 | B10: Audrey | C10: Iraq | D10: 3 | E10: Aymen Hussein
A11: P40339611 | B11: George Payne | C11: Mexico | D11: 1 | E11: Raul Jimenez
A12: P40339611 | B12: George Payne | C12: South Korea | D12: 2 | E12: Son Heung-min | F12: conceded
A13: P40339611 | B13: George Payne | C13: South Africa | D13: 3 | E13: Themba Zwane
A14: P2566247 | B14: Patrick Harrison | C14: Senegal | D14: 1 | E14: Sadio Mane
A15: P2566247 | B15: Patrick Harrison | C15: Australia | D15: 2 | E15: Nestory Irankunda | F15: conceded
A16: P2566247 | B16: Patrick Harrison | C16: Scotland | D16: 3 | E16: Scott McTominay
A17: P5028919 | B17: Chun-Ho | C17: Spain | D17: 1 | E17: Mikel Oyarzabal
A18: P5028919 | B18: Chun-Ho | C18: Iran | D18: 2 | E18: Mehdi Taremi | F18: scored
A19: P5028919 | B19: Chun-Ho | C19: New Zealand | D19: 3 | E19: Chris Wood
A20: P32865210 | B20: Connor Morgan | C20: Germany | D20: 1 | E20: Kai Havertz
A21: P32865210 | B21: Connor Morgan | C21: Austria | D21: 2 | E21: Marko Arnautovic | F21: scored
A22: P32865210 | B22: Connor Morgan | C22: Curacao | D22: 3 | E22: Jurgen Locadia
A23: P8749573 | B23: Drew Whittaker | C23: Croatia | D23: 1 | E23: Andrej Kramaric
A24: P8749573 | B24: Drew Whittaker | C24: Ivory Coast | D24: 2 | E24: Seko Fofana | F24: conceded
A25: P8749573 | B25: Drew Whittaker | C25: Cape Verde | D25: 3 | E25: Dailon Livramento
A26: P8241942 | B26: Chris Barrow | C26: Belgium | D26: 1 | E26: Romelu Lukaku
A27: P8241942 | B27: Chris Barrow | C27: Panama | D27: 2 | E27: Ismael Diaz | F27: conceded
A28: P8241942 | B28: Chris Barrow | C28: DR Congo | D28: 3 | E28: Cedric Bakambu
A29: P6355314 | B29: Dan Newton | C29: United States | D29: 1 | E29: Christian Pulisic
A30: P6355314 | B30: Dan Newton | C30: Switzerland | D30: 2 | E30: Dan Ndoye | F30: scored
A31: P6355314 | B31: Dan Newton | C31: Qatar | D31: 3 | E31: Akram Afif
A32: P96781613 | B32: Paul | C32: Netherlands | D32: 1 | E32: Memphis Depay
A33: P96781613 | B33: Paul | C33: Turkey | D33: 2 | E33: Arda Guler | F33: scored
A34: P96781613 | B34: Paul | C34: Saudi Arabia | D34: 3 | E34: Salem Al-Dawsari
A35: P2845818 | B35: James Pemberton | C35: France | D35: 1 | E35: Kylian Mbappe
A36: P2845818 | B36: James Pemberton | C36: Norway | D36: 2 | E36: Erling Haaland | F36: scored
A37: P2845818 | B37: James Pemberton | C37: Jordan | D37: 3 | E37: Musa Al-Taamari
A38: P2457756 | B38: Jordan | C38: England | D38: 1 | E38: Harry Kane
A39: P2457756 | B39: Jordan | C39: Algeria | D39: 2 | E39: Mohamed Amoura | F39: scored
A40: P2457756 | B40: Jordan | C40: Bosnia and Herzegovina | D40: 3 | E40: Edin Dzeko
...

Sheet KnockoutTeams
A1: Team Name | B1: Flag Emoji | C1: Price
A2: Argentina
A3: Spain
A4: France
A5: England
A6: Portugal
A7: Brazil
A8: Morocco
A9: Netherlands
A10: Belgium
A11: Germany
A12: Croatia
A13: Colombia
... A33: South Africa

Sheet KnockoutAllocations
A1: Player ID | B1: Player Name | C1: Team Name | D1: Tier
A2: P4895871 | B2: Tim Pickup | C2: Spain | D2: 1
A3: P8241942 | B3: Chris Barrow | C3: Argentina | D3: 1
A4: P8749573 | B4: Drew Whittaker | C4: France | D4: 1
A5: P6355314 | B5: Dan Newton | C5: England | D5: 1
A6: P8907665 | B6: Gregor Fotheringham | C6: Brazil | D6: 1
A7: P2457756 | B7: Jordan | C7: Netherlands | D7: 1
A8: P2566247 | B8: Patrick Harrison | C8: Germany | D8: 1
A9: P2845818 | B9: James Pemberton | C9: Germany | D9: 1
A10: P5028919 | B10: Chun-Ho | C10: Spain | D10: 1
A11: P32865210 | B11: Connor Morgan | C11: Portugal | D11: 1
A12: P40339611 | B12: George Payne | C12: Portugal | D12: 1
A13: P79919012 | B13: Ryan Harlow | C13: Brazil | D13: 1
... A61: P76426320 | B61: Kidd | C61: Ivory Coast | D61: 3

Sheet KnockoutPreferences
A1: Player ID | B1: Player Name | C1: Team Name | D1: Tier | E1: Captain Name | F1: 2 Mechanism

Sheet Matches
A1: Match ID | B1: Date | C1: Stage | D1: Group | E1: Home Team | F1: Away Team | G1: Home Score | H1: Away Score
A2: 2026-001 | B2: 46184 | C2: Group Stage | D2: Group A | E2: Mexico | F2: South Africa | G2: 2 | H2: 0
A3: 2026-002 | B3: 46185 | C3: Group Stage | D3: Group A | E3: South Korea | F3: Czech Republic | G3: 2 | H3: 1
A4: 2026-003 | B4: 46185 | C4: Group Stage | D4: Group B | E4: Canada | F4: Bosnia and Herzegovina | G4: 1 | H4: 1
A5: 2026-005 | B5: 46187 | C5: Group Stage | D5: Group C | E5: Haiti | F5: Scotland | G5: 0 | H5: 1
A6: 2026-006 | B6: 46187 | C6: Group Stage | D6: Group D | E6: Australia | F6: Turkey | G6: 2 | H6: 0
A7: 2026-008 | B7: 46186 | C7: Group Stage | D7: Group B | E7: Qatar | F7: Switzerland | G7: 1 | H7: 1
A8: 2026-009 | B8: 46187 | C8: Group Stage | D8: Group E | E8: Ivory Coast | F8: Ecuador | G8: 1 | H8: 0
A9: 2026-010 | B9: 46187 | C9: Group Stage | D9: Group E | E9: Germany | F9: Curacao | G9: 7 | H9: 1
A10: 2026-012 | B10: 46188 | C10: Group Stage | D10: Group F | E10: Sweden | F10: Tunisia | G10: 5 | H10: 1
A11: 2026-007 | B11: 46186 | C11: Group Stage | D11: Group C | E11: Brazil | F11: Morocco | G11: 1 | H11: 1
A12: 2026-011 | B12: 46187 | C12: Group Stage | D12: Group F | E12: Netherlands | F12: Japan | G12: 2 | H12: 2
A13: 2026-013 | B13: 46188 | C13: Group Stage | D13: Group H | E13: Saudi Arabia | F13: Uruguay | G13: 1 | H13: 1
... A67: 2026-066 | B67: 46200 | C67: Group Stage | D67: Group H | E67: Uruguay | F67: Spain | G67: 0 | H67: 1

Sheet MatchEvents
A1: Match ID | B1: Event Type | C1: Team | D1: Player Name | E1: Minute | F1: Benefiting Team
A2: 2026-001 | B2: goal | C2: Mexico | D2: Julian Quinones | E2: 9
A3: 2026-001 | B3: goal | C3: Mexico | D3: Raul Jimenez | E3: 67
A4: 2026-001 | B4: red_card | C4: South Africa | D4: Sphephelo Sithole | E4: 49
A5: 2026-001 | B5: red_card | C5: South Africa | D5: Themba Zwane | E5: 84
A6: 2026-001 | B6: red_card | C6: Mexico | D6: Cesar Montes | E6: 90
A7: 2026-002 | B7: goal | C7: Czech Republic | D7: Ladislav Krejci | E7: 59
A8: 2026-002 | B8: goal | C8: South Korea | D8: Hwang In-beom | E8: 67
A9: 2026-002 | B9: goal | C9: South Korea | D9: Oh Hyeon-gyu | E9: 80
A10: 2026-003 | B10: goal | C10: Bosnia and Herzegovina | D10: Jovo Lukic | E10: 21
A11: 2026-003 | B11: goal | C11: Canada | D11: Cyle Larin | E11: 78
A12: 2026-005 | B12: goal | C12: Scotland | D12: John McGinn | E12: 28
A13: 2026-006 | B13: goal | C13: Australia | D13: Nestory Irankunda | E13: 27
... A15: 2026-008 | B15: goal | C15: Switzerland | D15: Breel Embolo | E15: 17
A16: 2026-008 | B16: own_goal | C16: Switzerland | D16: Miro Muheim | E16: 90 | F16: Qatar
A17: 2026-009 | B17: goal | C17: Ivory Coast | D17: Amad Diallo | E17: 90
A18: 2026-010 | B18: goal | C18: Germany | D18: Felix Nmecha | E18: 6
A19: 2026-010 | B19: goal | C19: Curacao | D19: Livano Comenencia | E19: 21
A20: 2026-010 | B20: goal | C20: Germany | D20: Nico Schlotterbeck | E20: 38
A21: 2026-010 | B21: goal | C21: Germany | D21: Kai Havertz | E21: 45
A22: 2026-010 | B22: goal | C22: Germany | D22: Jamal Musiala | E22: 47
A23: 2026-010 | B23: goal | C23: Germany | D23: Nathaniel Brown | E23: 68
A24: 2026-010 | B24: goal | C24: Germany | D24: Deniz Undav | E24: 78
A25: 2026-010 | B25: goal | C25: Germany | D25: Kai Havertz | E25: 88
A26: 2026-012 | B26: goal | C26: Sweden | D26: Yasin Ayari | E26: 7
A27: 2026-012 | B27: goal | C27: Sweden | D27: Alexander Isak | E27: 30
A28: 2026-012 | B28: goal | C28: Tunisia | D28: Omar Rekik | E28: 43
... A44: 2026-015 | B44: goal | C44: Iran | D44: Mohammad Mohebi | E44: 64
A45: 2026-004 | B45: own_goal | C45: Paraguay | D45: Damian Bobadilla | E45: 7 | F45: United States
A46: 2026-004 | B46: goal | C46: United States | D46: Folarin Balogun | E46: 31
A47: 2026-004 | B47: goal | C47: United States | D47: Folarin Balogun | E47: 45
A48: 2026-004 | B48: goal | C48: Paraguay | D48: Mauricio | E48: 73
A49: 2026-004 | B49: goal | C49: United States | D49: Giovanni Reyna | E49: 90
A50: 2026-016 | B50: goal | C50: Egypt | D50: Emam Ashour | E50: 19
A51: 2026-016 | B51: own_goal | C51: Egypt | D51: Mohamed Hany | E51: 66 | F51: Belgium
A52: 2026-017 | B52: goal | C52: France | D52: Kylian Mbappe | E52: 66
A53: 2026-017 | B53: goal | C53: France | D53: Bradley Barcola | E53: 82
A54: 2026-017 | B54: goal | C54: Senegal | D54: Ibrahim Mbaye | E54: 90
A55: 2026-017 | B55: goal | C55: France | D55: Kylian Mbappe | E55: 90
A56: 2026-019 | B56: goal | C56: Argentina | D56: Lionel Messi | E56: 17
...

Sheet PointsActivity
A1: Match ID | B1: Event Type | C1: Event Team | D1: Player Team | E1: Event Player | F1: Minute | G1: Player ID | H1: Player Name | I1: Points | J1: Category
A2: 2026-001 | B2: Goal | C2: Mexico | D2: Mexico | E2: Julian Quinones | F2: 9 | G2: P40339611 | H2: George Payne | I2: 1 | J2: Goals Scored
A3: 2026-001 | B3: Goal | C3: Mexico | D3: South Africa | E3: Julian Quinones | F3: 9 | G3: P40339611 | H3: George Payne | I3: 1 | J3: Goals Conceded
A4: 2026-001 | B4: Goal | C4: Mexico | D4: Mexico | E4: Raul Jimenez | F4: 67 | G4: P40339611 | H4: George Payne | I4: 1 | J4: Goals Scored
A5: 2026-001 | B5: Captain Goal | C5: Mexico | D5: Mexico | E5: Raul Jimenez | F5: 67 | G5: P40339611 | H5: George Payne | I5: 2 | J5: Goals Scored
A6: 2026-001 | B6: Goal | C6: Mexico | D6: South Africa | E6: Raul Jimenez | F6: 67 | G6: P40339611 | H6: George Payne | I6: 1 | J6: Goals Conceded
A7: 2026-001 | B7: Red Card | C7: South Africa | D7: South Africa | E7: Sphephelo Sithole | F7: 49 | G7: P40339611 | H7: George Payne | I7: -2 | J7: Cards
A8: 2026-001 | B8: Red Card | C8: South Africa | D8: South Africa | E8: Themba Zwane | F8: 84 | G8: P40339611 | H8: George Payne | I8: -2 | J8: Cards
A9: 2026-001 | B9: Red Card | C9: Mexico | D9: Mexico | E9: Cesar Montes | F9: 90 | G9: P40339611 | H9: George Payne | I9: -2 | J9: Cards
A10: 2026-002 | B10: Goal | C10: Czech Republic | D10: Czech Republic | E10: Ladislav Krejci | F10: 59 | G10: P79919012 | H10: Ryan Harlow | I10: 1 | J10: Goals Scored
A11: 2026-002 | B11: Goal | C11: Czech Republic | D11: South Korea | E11: Ladislav Krejci | F11: 59 | G11: P40339611 | H11: George Payne | I11: 1 | J11: Goals Conceded
A12: 2026-003 | B12: Goal | C12: Canada | D12: Bosnia and Herzegovina | E12: Cyle Larin | F12: 78 | G12: P2457756 | H12: Jordan | I12: 1 | J12: Goals Conceded
A13: 2026-003 | B13: Goal | C13: Canada | D13: Canada | E13: Cyle Larin | F13: 78 | G13: P55168715 | H13: Audrey | I13: 1 | J13: Goals Scored
... A399: 2026-066 | B399: Goal | C399: Spain | D399: Spain | E399: Alex Baena | F399: 42 | G399: P5028919 | H399: Chun-Ho | I399: 1 | J399: Goals Scored
A400: 2026-001 | B400: Match Win | C400: Mexico | D400: Mexico | G400: P40339611 | H400: George Payne | I400: 3 | J400: Match Win
A401: 2026-002 | B401: Match Win | C401: South Korea | D401: South Korea | G401: P40339611 | H401: George Payne | I401: 3 | J401: Match Win
A402: 2026-003 | B402: Match Draw | C402: Bosnia and Herzegovina | D402: Bosnia and Herzegovina | G402: P2457756 | H402: Jordan | I402: 1 | J402: Match Draw
A403: 2026-003 | B403: Match Draw | C403: Canada | D403: Canada | G403: P55168715 | H403: Audrey | I403: 1 | J403: Match Draw
A404: 2026-005 | B404: Match Win | C404: Scotland | D404: Scotland | G404: P2566247 | H404: Patrick Harrison | I404: 3 | J404: Match Win
A405: 2026-006 | B405: Match Win | C405: Australia | D405: Australia | G405: P2566247 | H405: Patrick Harrison | I405: 3 | J405: Match Win
A406: 2026-008 | B406: Match Draw | C406: Qatar | D406: Qatar | G406: P76426320 | H406: Kidd | I406: 1 | J406: Match Draw
A407: 2026-008 | B407: Match Draw | C407: Qatar | D407: Qatar | G407: P6355314 | H407: Dan Newton | I407: 1 | J407: Match Draw
A408: 2026-008 | B408: Match Draw | C408: Switzerland | D408: Switzerland | G408: P6355314 | H408: Dan Newton | I408: 1 | J408: Match Draw
A409: 2026-009 | B409: Match Win | C409: Ivory Coast | D409: Ivory Coast | G409: P8749573 | H409: Drew Whittaker | I409: 3 | J409: Match Win
A410: 2026-009 | B410: Match Win | C410: Ivory Coast | D410: Ivory Coast | G410: P39011219 | H410: Jak Kenworthy | I410: 3 | J410: Match Win
A411: 2026-010 | B411: Match Win | C411: Germany | D411: Germany | G411: P32865210 | H411: Connor Morgan | I411: 3 | J411: Match Win
... A509: 2026-066 | B509: Match Win | C509: Spain | D509: Spain | G509: P5028919 | H509: Chun-Ho | I509: 3 | J509: Match Win

Sheet Leaderboard
A1: Rank | B1: Player ID | C1: Player Name | D1: Total Points | E1: Goal Points | F1: Captain Points | G1: Result Points | H1: Penalty Points
A2: =RANK(D2,D:D) -> 12 | B2: P4895871 | C2: Tim Pickup | D2: =SUM(E2:H2) -> 24 | E2: =SUMIFS(PointsActivity!$I:$I,PointsActivity!$B:$B,"Goal",PointsActivity!$G:$G,$B2) -> 16 | F2: =SUMIFS(PointsActivity!$I:$I,PointsActivity!$B:$B,"Captain Goal",PointsActivity!$G:$G,$B2) + SUMIFS(PointsActivity!$I:$I,PointsActivity!$B:$B,"Captain Assist",PointsActivity!$G:$G,$B2) -> 0 | G2: =SUMIFS(PointsActivity!$I:$I,PointsActivity!$B:$B,"Match Win",PointsActivity!$G:$G,$B2) + SUMIFS(PointsActivity!$I:$I,PointsActivity!$B:$B,"Match Draw",PointsActivity!$G:$G,$B2) -> 8 | H2: =SUMIFS(PointsActivity!$I:$I,PointsActivity!$B:$B,"Own Goal",PointsActivity!$G:$G,$B2) + SUMIFS(PointsActivity!$I:$I,PointsActivity!$B:$B,"Red Card",PointsActivity!$G:$G,$B2) -> 0
A3: =RANK(D3,D:D) -> 20 | B3: P8241942 | C3: Chris Barrow | D3: =SUM(E3:H3) -> 14 | E3: =SUMIFS(PointsActivity!$I:$I,PointsActivity!$B:$B,"Goal",PointsActivity!$G:$G,$B3) -> 10 | F3: =SUMIFS(PointsActivity!$I:$I,PointsActivity!$B:$B,"Captain Goal",PointsActivity!$G:$G,$B3) + SUMIFS(PointsActivity!$I:$I,PointsActivity!$B:$B,"Captain Assist",PointsActivity!$G:$G,$B3) -> 0 | G3: =SUMIFS(PointsActivity!$I:$I,PointsActivity!$B:$B,"Match Win",PointsActivity!$G:$G,$B3) + SUMIFS(PointsActivity!$I:$I,PointsActivity!$B:$B,"Match Draw",PointsActivity!$G:$G,$B3) -> 6 | H3: =SUMIFS(PointsActivity!$I:$I,PointsActivity!$B:$B,"Own Goal",PointsActivity!$G:$G,$B3) + SUMIFS(PointsActivity!$I:$I,PointsActivity!$B:$B,"Red Card",PointsActivity!$G:$G,$B3) -> -2
A4: =RANK(D4,D:D) -> 18 | B4: P8749573 | C4: Drew Whittaker | D4: =SUM(E4:H4) -> 19 | E4: =SUMIFS(PointsActivity!$I:$I,PointsActivity!$B:$B,"Goal",PointsActivity!$G:$G,$B4) -> 7 | F4: =SUMIFS(PointsActivity!$I:$I,PointsActivity!$B:$B,"Captain Goal",PointsActivity!$G:$G,$B4) + SUMIFS(PointsActivity!$I:$I,PointsActivity!$B:$B,"Captain Assist",PointsActivity!$G:$G,$B4) -> 0 | G4: =SUMIFS(PointsActivity!$I:$I,PointsActivity!$B:$B,"Match Win",PointsActivity!$G:$G,$B4) + SUMIFS(PointsActivity!$I:$I,PointsActivity!$B:$B,"Match Draw",PointsActivity!$G:$G,$B4) -> 12 | H4: =SUMIFS(PointsActivity!$I:$I,PointsActivity!$B:$B,"Own Goal",PointsActivity!$G:$G,$B4) + SUMIFS(PointsActivity!$I:$I,PointsActivity!$B:$B,"Red Card",PointsActivity!$G:$G,$B4) -> 0
A5: =RANK(D5,D:D) -> 9 | B5: P6355314 | C5: Dan Newton | D5: =SUM(E5:H5) -> 29 | E5: =SUMIFS(PointsActivity!$I:$I,PointsActivity!$B:$B,"Goal",PointsActivity!$G:$G,$B5) -> 25 | F5: =SUMIFS(PointsActivity!$I:$I,PointsActivity!$B:$B,"Captain Goal",PointsActivity!$G:$G,$B5) + SUMIFS(PointsActivity!$I:$I,PointsActivity!$B:$B,"Captain Assist",PointsActivity!$G:$G,$B5) -> 0 | G5: =SUMIFS(PointsActivity!$I:$I,PointsActivity!$B:$B,"Match Win",PointsActivity!$G:$G,$B5) + SUMIFS(PointsActivity!$I:$I,PointsActivity!$B:$B,"Match Draw",PointsActivity!$G:$G,$B5) -> 14 | H5: =SUMIFS(PointsActivity!$I:$I,PointsActivity!$B:$B,"Own Goal",PointsActivity!$G:$G,$B5) + SUMIFS(PointsActivity!$I:$I,PointsActivity!$B:$B,"Red Card",PointsActivity!$G:$G,$B5) -> -10
A6: =RANK(D6,D:D) -> 2 | B6: P8907665 | C6: Gregor Fotheringham | D6: =SUM(E6:H6) -> 45 | E6: =SUMIFS(PointsActivity!$I:$I,PointsActivity!$B:$B,"Goal",PointsActivity!$G:$G,$B6) -> 24 | F6: =SUMIFS(PointsActivity!$I:$I,PointsActivity!$B:$B,"Captain Goal",PointsActivity!$G:$G,$B6) + SUMIFS(PointsActivity!$I:$I,PointsActivity!$B:$B,"Captain Assist",PointsActivity!$G:$G,$B6) -> 12 | G6: =SUMIFS(PointsActivity!$I:$I,PointsActivity!$B:$B,"Match Win",PointsActivity!$G:$G,$B6) + SUMIFS(PointsActivity!$I:$I,PointsActivity!$B:$B,"Match Draw",PointsActivity!$G:$G,$B6) -> 11 | H6: =SUMIFS(PointsActivity!$I:$I,PointsActivity!$B:$B,"Own Goal",PointsActivity!$G:$G,$B6) + SUMIFS(PointsActivity!$I:$I,PointsActivity!$B:$B,"Red Card",PointsActivity!$G:$G,$B6) -> -2
A7: =RANK(D7,D:D) -> 11 | B7: P2457756 | C7: Jordan | D7: =SUM(E7:H7) -> 25 | E7: =SUMIFS(PointsActivity!$I:$I,PointsActivity!$B:$B,"Goal",PointsActivity!$G:$G,$B7) -> 12 | F7: =SUMIFS(PointsActivity!$I:$I,PointsActivity!$B:$B,"Captain Goal",PointsActivity!$G:$G,$B7) + SUMIFS(PointsActivity!$I:$I,PointsActivity!$B:$B,"Captain Assist",PointsActivity!$G:$G,$B7) -> 4 | G7: =SUMIFS(PointsActivity!$I:$I,PointsActivity!$B:$B,"Match Win",PointsActivity!$G:$G,$B7) + SUMIFS(PointsActivity!$I:$I,PointsActivity!$B:$B,"Match Draw",PointsActivity!$G:$G,$B7) -> 11 | H7: =SUMIFS(PointsActivity!$I:$I,PointsActivity!$B:$B,"Own Goal",PointsActivity!$G:$G,$B7) + SUMIFS(PointsActivity!$I:$I,PointsActivity!$B:$B,"Red Card",PointsActivity!$G:$G,$B7) -> -2
A8: =RANK(D8,D:D) -> 12 | B8: P2566247 | C8: Patrick Harrison | D8: =SUM(E8:H8) -> 24 | E8: =SUMIFS(PointsActivity!$I:$I,PointsActivity!$B:$B,"Goal",PointsActivity!$G:$G,$B8) -> 14 | F8: =SUMIFS(PointsActivity!$I:$I,PointsActivity!$B:$B,"Captain Goal",PointsActivity!$G:$G,$B8) + SUMIFS(PointsActivity!$I:$I,PointsActivity!$B:$B,"Captain Assist",PointsActivity!$G:$G,$B8) -> 2 | G8: =SUMIFS(PointsActivity!$I:$I,PointsActivity!$B:$B,"Match Win",PointsActivity!$G:$G,$B8) + SUMIFS(PointsActivity!$I:$I,PointsActivity!$B:$B,"Match Draw",PointsActivity!$G:$G,$B8) -> 10 | H8: =SUMIFS(PointsActivity!$I:$I,PointsActivity!$B:$B,"Own Goal",PointsActivity!$G:$G,$B8) + SUMIFS(PointsActivity!$I:$I,PointsActivity!$B:$B,"Red Card",PointsActivity!$G:$G,$B8) -> -2
A9: =RANK(D9,D:D) -> 1 | B9: P2845818 | C9: James Pemberton | D9: =SUM(E9:H9) -> 52 | E9: =SUMIFS(PointsActivity!$I:$I,PointsActivity!$B:$B,"Goal",PointsActivity!$G:$G,$B9) -> 23 | F9: =SUMIFS(PointsActivity!$I:$I,PointsActivity!$B:$B,"Captain Goal",PointsActivity!$G:$G,$B9) + SUMIFS(PointsActivity!$I:$I,PointsActivity!$B:$B,"Captain Assist",PointsActivity!$G:$G,$B9) -> 16 | G9: =SUMIFS(PointsActivity!$I:$I,PointsActivity!$B:$B,"Match Win",PointsActivity!$G:$G,$B9) + SUMIFS(PointsActivity!$I:$I,PointsActivity!$B:$B,"Match Draw",PointsActivity!$G:$G,$B9) -> 15 | H9: =SUMIFS(PointsActivity!$I:$I,PointsActivity!$B:$B,"Own Goal",PointsActivity!$G:$G,$B9) + SUMIFS(PointsActivity!$I:$I,PointsActivity!$B:$B,"Red Card",PointsActivity!$G:$G,$B9) -> -2
A10: =RANK(D10,D:D) -> 7 | B10: P5028919 | C10: Chun-Ho | D10: =SUM(E10:H10) -> 33 | E10: =SUMIFS(PointsActivity!$I:$I,PointsActivity!$B:$B,"Goal",PointsActivity!$G:$G,$B10) -> 18 | F10: =SUMIFS(PointsActivity!$I:$I,PointsActivity!$B:$B,"Captain Goal",PointsActivity!$G:$G,$B10) + SUMIFS(PointsActivity!$I:$I,PointsActivity!$B:$B,"Captain Assist",PointsActivity!$G:$G,$B10) -> 4 | G10: =SUMIFS(PointsActivity!$I:$I,PointsActivity!$B:$B,"Match Win",PointsActivity!$G:$G,$B10) + SUMIFS(PointsActivity!$I:$I,PointsActivity!$B:$B,"Match Draw",PointsActivity!$G:$G,$B10) -> 11 | H10: =SUMIFS(PointsActivity!$I:$I,PointsActivity!$B:$B,"Own Goal",PointsActivity!$G:$G,$B10) + SUMIFS(PointsActivity!$I:$I,PointsActivity!$B:$B,"Red Card",PointsActivity!$G:$G,$B10) -> 0
A11: =RANK(D11,D:D) -> 4 | B11: P32865210 | C11: Connor Morgan | D11: =SUM(E11:H11) -> 38 | E11: =SUMIFS(PointsActivity!$I:$I,PointsActivity!$B:$B,"Goal",PointsActivity!$G:$G,$B11) -> 22 | F11: =SUMIFS(PointsActivity!$I:$I,PointsActivity!$B:$B,"Captain Goal",PointsActivity!$G:$G,$B11) + SUMIFS(PointsActivity!$I:$I,PointsActivity!$B:$B,"Captain Assist",PointsActivity!$G:$G,$B11) -> 6 | G11: =SUMIFS(PointsActivity!$I:$I,PointsActivity!$B:$B,"Match Win",PointsActivity!$G:$G,$B11) + SUMIFS(PointsActivity!$I:$I,PointsActivity!$B:$B,"Match Draw",PointsActivity!$G:$G,$B11) -> 10 | H11: =SUMIFS(PointsActivity!$I:$I,PointsActivity!$B:$B,"Own Goal",PointsActivity!$G:$G,$B11) + SUMIFS(PointsActivity!$I:$I,PointsActivity!$B:$B,"Red Card",PointsActivity!$G:$G,$B11) -> 0
A12: =RANK(D12,D:D) -> 12 | B12: P40339611 | C12: George Payne | D12: =SUM(E12:H12) -> 24 | E12: =SUMIFS(PointsActivity!$I:$I,PointsActivity!$B:$B,"Goal",PointsActivity!$G:$G,$B12) -> 12 | F12: =SUMIFS(PointsActivity!$I:$I,PointsActivity!$B:$B,"Captain Goal",PointsActivity!$G:$G,$B12) + SUMIFS(PointsActivity!$I:$I,PointsActivity!$B:$B,"Captain Assist",PointsActivity!$G:$G,$B12) -> 2 | G12: =SUMIFS(PointsActivity!$I:$I,PointsActivity!$B:$B,"Match Win",PointsActivity!$G:$G,$B12) + SUMIFS(PointsActivity!$I:$I,PointsActivity!$B:$B,"Match Draw",PointsActivity!$G:$G,$B12) -> 16 | H12: =SUMIFS(PointsActivity!$I:$I,PointsActivity!$B:$B,"Own Goal",PointsActivity!$G:$G,$B12) + SUMIFS(PointsActivity!$I:$I,PointsActivity!$B:$B,"Red Card",PointsActivity!$G:$G,$B12) -> -6
A13: =RANK(D13,D:D) -> 18 | B13: P79919012 | C13: Ryan Harlow | D13: =SUM(E13:H13) -> 19 | E13: =SUMIFS(PointsActivity!$I:$I,PointsActivity!$B:$B,"Goal",PointsActivity!$G:$G,$B13) -> 10 | F13: =SUMIFS(PointsActivity!$I:$I,PointsActivity!$B:$B,"Captain Goal",PointsActivity!$G:$G,$B13) + SUMIFS(PointsActivity!$I:$I,PointsActivity!$B:$B,"Captain Assist",PointsActivity!$G:$G,$B13) -> 2 | G13: =SUMIFS(PointsActivity!$I:$I,PointsActivity!$B:$B,"Match Win",PointsActivity!$G:$G,$B13) + SUMIFS(PointsActivity!$I:$I,PointsActivity!$B:$B,"Match Draw",PointsActivity!$G:$G,$B13) -> 11 | H13: =SUMIFS(PointsActivity!$I:$I,PointsActivity!$B:$B,"Own Goal",PointsActivity!$G:$G,$B13) + SUMIFS(PointsActivity!$I:$I,PointsActivity!$B:$B,"Red Card",PointsActivity!$G:$G,$B13) -> -4
... A21: =RANK(D21,D:D) -> 16 | B21: P76426320 | C21: Kidd | D21: =SUM(E21:H21) -> 21 | E21: =SUMIFS(PointsActivity!$I:$I,PointsActivity!$B:$B,"Goal",PointsActivity!$G:$G,$B21) -> 18 | F21: =SUMIFS(PointsActivity!$I:$I,PointsActivity!$B:$B,"Captain Goal",PointsActivity!$G:$G,$B21) + SUMIFS(PointsActivity!$I:$I,PointsActivity!$B:$B,"Captain Assist",PointsActivity!$G:$G,$B21) -> 2 | G21: =SUMIFS(PointsActivity!$I:$I,PointsActivity!$B:$B,"Match Win",PointsActivity!$G:$G,$B21) + SUMIFS(PointsActivity!$I:$I,PointsActivity!$B:$B,"Match Draw",PointsActivity!$G:$G,$B21) -> 11 | H21: =SUMIFS(PointsActivity!$I:$I,PointsActivity!$B:$B,"Own Goal",PointsActivity!$G:$G,$B21) + SUMIFS(PointsActivity!$I:$I,PointsActivity!$B:$B,"Red Card",PointsActivity!$G:$G,$B21) -> -10
